#VRML_SIM R2025b utf8

EXTERNPROTO "https://raw.githubusercontent.com/cyberbotics/webots/R2022b/projects/objects/backgrounds/protos/TexturedBackground.proto"
EXTERNPROTO "https://raw.githubusercontent.com/cyberbotics/webots/R2022b/projects/objects/floors/protos/RectangleArena.proto"
EXTERNPROTO "https://raw.githubusercontent.com/cyberbotics/webots/R2022b/projects/objects/backgrounds/protos/TexturedBackgroundLight.proto"

WorldInfo {
  info [
    "Simple world."
  ]
  title "Simple floor"
}
Viewpoint {
  orientation -0.020382787773359133 0.9991592330071086 0.03557202635825916 1.0415250924266573
  position -0.8981631983556829 -0.10581398645476614 1.4840553976650943
  bloomThreshold 0.5
}
TexturedBackground {
}
TexturedBackgroundLight {
}
RectangleArena {
}
Robot {
  translation 0 -3.588059559180158e-10 -0.00021911902082535906
  rotation -1 0 0 3.300834640862455e-08
  children [
    HingeJoint {
      jointParameters HingeJointParameters {
        position 1.7973645737361435e-07
        axis 0 1 0
        anchor 0 0 0.025
      }
      device [
        RotationalMotor {
          name "left wheel motor"
        }
      ]
      endPoint Solid {
        translation 0 0.045 0.025
        rotation 0 1 0 1.7881393432617193e-07
        children [
          DEF WHEEL Pose {
            rotation 1 0 0 1.5707996938995747
            children [
              Shape {
                appearance PBRAppearance {
                  baseColor 1 0 0
                  roughness 1
                  metalness 0
                }
                geometry Cylinder {
                  height 0.01
                  radius 0.025
                }
              }
            ]
          }
        ]
        name "left wheel"
        boundingObject USE WHEEL
        physics Physics {
        }
        linearVelocity 0 -2.2743780311205927e-15 -3.6172149348734533e-16
        angularVelocity 6.870998299669315e-14 0 0
      }
    }
    HingeJoint {
      jointParameters HingeJointParameters {
        position 1.7973649848749276e-07
        axis 0 1 0
        anchor 0 0 0.025
      }
      device [
        RotationalMotor {
          name "right wheel motor"
        }
      ]
      endPoint Solid {
        translation 0 -0.045 0.025
        rotation 0 1 0 1.7881393432617193e-07
        children [
          USE WHEEL
        ]
        name "right wheel"
        boundingObject USE WHEEL
        physics Physics {
        }
        linearVelocity 0 3.7139804399423086e-15 3.619591739621606e-16
        angularVelocity -1.545995990880745e-13 0 0
      }
    }
    Pose {
      translation 0 0 0.0415
      children [
        Shape {
          appearance PBRAppearance {
            baseColor 0 0 1
            roughness 1
            metalness 0
          }
          geometry DEF BODY Cylinder {
            height 0.08
            radius 0.045
          }
        }
      ]
    }
  ]
  boundingObject Pose {
    translation 0 0 0.0415
    children [
      USE BODY
    ]
  }
  physics Physics {
  }
  controller "simplebot_controller"
  linearVelocity 0 2.337102616135187e-15 -6.2546545834651535e-15
  angularVelocity -9.820461274317679e-14 0 0
}
